Outputs (Seed=227)/Order Generator Output.txt
D:\Athul\Quant Development\Matching Engine>g++ order_generator.cpp -o client.exe -lws2_32 && client.exe
1. { SELL, 100.000000, 75 }
2. { SELL, 101.250000, 25 }
3. { SELL, 100.750000, 25 }
4. { BUY, 101.750000, 100 }
5. { BUY, 101.750000, 75 }
6. { BUY, 100.500000, 75 }
7. { BUY, 100.250000, 100 }
8. { BUY, 100.250000, 25 }
9. { BUY, 100.000000, 50 }
10. { SELL, 101.250000, 100 }
11. { SELL, 101.000000, 50 }
12. { BUY, 102.000000, 100 }
13. { BUY, 101.000000, 100 }
14. { BUY, 101.750000, 100 }
15. { SELL, 101.750000, 100 }
16. { SELL, 100.250000, 100 }
17. { SELL, 101.000000, 50 }
18. { BUY, 100.500000, 100 }
19. { BUY, 102.000000, 100 }
20. { BUY, 100.500000, 25 }
21. { SELL, 101.500000, 25 }
22. { BUY, 102.000000, 100 }
23. { SELL, 102.000000, 50 }
24. { BUY, 100.500000, 50 }
25. { SELL, 101.000000, 75 }
26. { BUY, 101.000000, 50 }
27. { SELL, 101.750000, 25 }
28. { SELL, 102.000000, 25 }
29. { SELL, 100.250000, 100 }
30. { BUY, 100.250000, 25 }
31. { BUY, 100.750000, 75 }
32. { SELL, 101.250000, 100 }
33. { SELL, 100.750000, 25 }
34. { SELL, 101.000000, 75 }
35. { SELL, 102.000000, 50 }
36. { BUY, 101.250000, 75 }
37. { BUY, 101.000000, 25 }
38. { BUY, 101.500000, 75 }
39. { SELL, 100.750000, 25 }
40. { SELL, 100.250000, 25 }
41. { BUY, 100.750000, 25 }
42. { BUY, 100.000000, 25 }
43. { SELL, 101.000000, 25 }
44. { SELL, 101.250000, 75 }
45. { BUY, 101.250000, 75 }
46. { BUY, 100.000000, 100 }
47. { BUY, 100.000000, 75 }
48. { SELL, 100.500000, 25 }
49. { BUY, 100.750000, 50 }
50. { BUY, 101.000000, 25 }
51. { BUY, 101.250000, 50 }
52. { SELL, 100.250000, 75 }
53. { SELL, 100.500000, 75 }
54. { BUY, 101.500000, 75 }
55. { SELL, 101.750000, 75 }
56. { SELL, 101.000000, 50 }
57. { SELL, 102.000000, 100 }
58. { SELL, 102.000000, 50 }
59. { SELL, 100.500000, 75 }
60. { SELL, 100.000000, 75 }
61. { SELL, 101.750000, 100 }
62. { SELL, 100.000000, 50 }
63. { BUY, 102.000000, 100 }
64. { BUY, 101.000000, 25 }
65. { BUY, 101.250000, 100 }
66. { BUY, 101.500000, 75 }
67. { BUY, 100.750000, 25 }
68. { BUY, 102.000000, 25 }
69. { SELL, 100.500000, 50 }
70. { BUY, 100.500000, 100 }
71. { BUY, 100.250000, 100 }
72. { SELL, 101.250000, 75 }
73. { BUY, 101.250000, 100 }
74. { BUY, 100.500000, 50 }
75. { BUY, 100.000000, 25 }
76. { SELL, 101.000000, 100 }
77. { SELL, 100.500000, 100 }
78. { BUY, 101.000000, 75 }
79. { SELL, 100.750000, 75 }
80. { SELL, 100.000000, 50 }
81. { SELL, 101.500000, 50 }
82. { SELL, 100.000000, 100 }
83. { SELL, 100.000000, 75 }
84. { SELL, 101.250000, 100 }
85. { BUY, 100.000000, 50 }
86. { BUY, 101.500000, 100 }
87. { SELL, 101.250000, 75 }
88. { SELL, 102.000000, 50 }
89. { SELL, 100.500000, 75 }
90. { BUY, 101.500000, 50 }
91. { SELL, 101.000000, 50 }
92. { BUY, 101.750000, 25 }
93. { SELL, 100.750000, 25 }
94. { SELL, 101.250000, 100 }
95. { SELL, 101.500000, 75 }
96. { SELL, 101.750000, 100 }
97. { SELL, 100.750000, 25 }
98. { SELL, 101.500000, 50 }
99. { BUY, 101.000000, 50 }
100. { SELL, 101.000000, 100 }
101. { SELL, 100.000000, 50 }
102. { SELL, 100.750000, 50 }
103. { SELL, 101.000000, 75 }
104. { BUY, 101.000000, 75 }
105. { SELL, 101.750000, 50 }
106. { BUY, 100.500000, 25 }
107. { SELL, 100.250000, 75 }
108. { SELL, 100.000000, 75 }
109. { SELL, 102.000000, 25 }
110. { SELL, 100.250000, 100 }
111. { SELL, 101.000000, 75 }
112. { BUY, 101.500000, 50 }
113. { SELL, 101.250000, 75 }
114. { SELL, 100.750000, 25 }
115. { SELL, 100.500000, 50 }
116. { SELL, 101.750000, 25 }
117. { SELL, 100.500000, 75 }
118. { BUY, 101.000000, 100 }
119. { SELL, 101.500000, 75 }
120. { BUY, 102.000000, 50 }
121. { BUY, 100.000000, 50 }
122. { SELL, 101.750000, 50 }
123. { SELL, 101.000000, 100 }
124. { SELL, 101.500000, 75 }
125. { BUY, 101.250000, 25 }
126. { BUY, 101.500000, 50 }
127. { SELL, 101.750000, 100 }
128. { BUY, 101.000000, 75 }
129. { BUY, 101.500000, 25 }
130. { BUY, 100.250000, 25 }
131. { SELL, 101.250000, 100 }
132. { BUY, 102.000000, 100 }
133. { SELL, 101.750000, 100 }
134. { SELL, 100.000000, 100 }
135. { SELL, 101.250000, 75 }
136. { SELL, 100.750000, 75 }
137. { SELL, 101.500000, 100 }
138. { BUY, 101.750000, 25 }
139. { BUY, 100.500000, 75 }
140. { SELL, 101.250000, 25 }
141. { BUY, 101.750000, 75 }
142. { BUY, 101.750000, 75 }
143. { BUY, 101.250000, 50 }
144. { SELL, 101.000000, 75 }
145. { BUY, 101.750000, 50 }
146. { BUY, 101.750000, 100 }
147. { BUY, 101.500000, 25 }
148. { SELL, 102.000000, 100 }
149. { BUY, 102.000000, 25 }
150. { BUY, 101.750000, 50 }
151. { SELL, 102.000000, 75 }
152. { SELL, 100.750000, 25 }
153. { BUY, 101.500000, 50 }
154. { BUY, 101.000000, 75 }
155. { SELL, 100.500000, 100 }
156. { SELL, 100.000000, 100 }
157. { SELL, 100.500000, 25 }
158. { SELL, 100.750000, 100 }
159. { SELL, 101.750000, 75 }
160. { SELL, 101.250000, 100 }
161. { SELL, 102.000000, 50 }
162. { SELL, 101.250000, 100 }
163. { BUY, 100.000000, 25 }
164. { SELL, 101.000000, 100 }
165. { BUY, 100.000000, 75 }
166. { SELL, 100.750000, 100 }
167. { SELL, 100.250000, 50 }
168. { BUY, 100.750000, 75 }
169. { BUY, 102.000000, 25 }
170. { BUY, 101.250000, 25 }
171. { SELL, 100.000000, 75 }
172. { SELL, 100.750000, 25 }
173. { BUY, 100.250000, 100 }
174. { SELL, 101.000000, 25 }
175. { BUY, 101.500000, 50 }
176. { SELL, 100.750000, 50 }
177. { BUY, 100.000000, 25 }
178. { BUY, 100.750000, 25 }
179. { SELL, 101.250000, 100 }
180. { BUY, 101.000000, 75 }
181. { BUY, 101.250000, 50 }
182. { BUY, 102.000000, 100 }
183. { BUY, 100.250000, 25 }
184. { BUY, 100.750000, 100 }
185. { SELL, 100.750000, 25 }
186. { BUY, 101.750000, 75 }
187. { BUY, 101.250000, 50 }
188. { BUY, 101.500000, 25 }
189. { BUY, 100.750000, 100 }
190. { SELL, 101.500000, 50 }
191. { SELL, 101.500000, 50 }
192. { SELL, 100.750000, 25 }
193. { SELL, 100.250000, 50 }
194. { SELL, 100.000000, 50 }
195. { BUY, 101.500000, 100 }
196. { SELL, 101.250000, 100 }
197. { SELL, 101.000000, 75 }
198. { BUY, 101.250000, 50 }
199. { SELL, 100.000000, 75 }
200. { BUY, 101.000000, 50 }
201. { BUY, 100.750000, 25 }
202. { BUY, 100.000000, 75 }
203. { BUY, 101.250000, 100 }
204. { BUY, 100.750000, 75 }
205. { SELL, 100.500000, 100 }
206. { SELL, 100.000000, 50 }
207. { SELL, 101.750000, 100 }
208. { SELL, 102.000000, 50 }
209. { BUY, 102.000000, 25 }
210. { SELL, 100.750000, 50 }
211. { BUY, 101.250000, 100 }
212. { BUY, 100.750000, 50 }
213. { SELL, 101.000000, 50 }
214. { SELL, 100.000000, 25 }
215. { SELL, 100.500000, 100 }
216. { SELL, 101.250000, 50 }
217. { BUY, 100.000000, 25 }
218. { SELL, 101.000000, 25 }
219. { BUY, 100.500000, 100 }
220. { BUY, 101.750000, 100 }
221. { BUY, 101.000000, 100 }
222. { BUY, 101.500000, 100 }
223. { SELL, 100.250000, 75 }
224. { SELL, 101.000000, 25 }
225. { BUY, 100.750000, 25 }
226. { SELL, 100.000000, 25 }
227. { BUY, 100.000000, 50 }
228. { BUY, 101.000000, 25 }
229. { SELL, 100.000000, 100 }
230. { SELL, 101.250000, 25 }
231. { SELL, 100.750000, 75 }
232. { BUY, 101.000000, 50 }
233. { BUY, 100.250000, 75 }
234. { SELL, 101.500000, 100 }
235. { BUY, 101.500000, 50 }
236. { SELL, 100.500000, 25 }
237. { BUY, 100.000000, 25 }
238. { SELL, 100.250000, 25 }
239. { BUY, 100.750000, 75 }
240. { BUY, 101.250000, 75 }
241. { BUY, 101.500000, 100 }
242. { SELL, 101.750000, 75 }
243. { BUY, 100.500000, 50 }
244. { SELL, 101.000000, 75 }
245. { BUY, 100.750000, 25 }
246. { SELL, 100.500000, 100 }
247. { SELL, 100.500000, 25 }
248. { SELL, 101.500000, 100 }
249. { BUY, 101.000000, 100 }
250. { BUY, 100.250000, 100 }
251. { SELL, 100.250000, 25 }
252. { SELL, 101.500000, 100 }
253. { SELL, 101.750000, 75 }
254. { SELL, 100.500000, 75 }
255. { BUY, 100.500000, 50 }
256. { BUY, 101.250000, 25 }
257. { BUY, 100.750000, 25 }
258. { SELL, 101.250000, 50 }
259. { BUY, 101.750000, 25 }
260. { BUY, 101.250000, 25 }
