Outputs (Seed=722)/Matching Engine Output (Buy equal to Sell).txt
D:\Athul\Quant Development\Matching Engine>g++ matching_engine.cpp -o server.exe -lws2_32 && server.exe
1. Buy ID: 4,   Sell ID: 4,     Price: 101.25,  Quantity: 25,   Timestamp: Mon Jul 24 15:05:10 2023
Total Trades = 1
Engine Profit = 0
2. Buy ID: 7,   Sell ID: 6,     Price: 100.75,  Quantity: 25,   Timestamp: Mon Jul 24 15:05:11 2023
3. Buy ID: 10,  Sell ID: 5,     Price: 101,     Quantity: 25,   Timestamp: Mon Jul 24 15:05:11 2023
4. Buy ID: 11,  Sell ID: 3,     Price: 100.5,   Quantity: 25,   Timestamp: Mon Jul 24 15:05:11 2023
5. Buy ID: 23,  Sell ID: 17,    Price: 101.5,   Quantity: 25,   Timestamp: Mon Jul 24 15:05:11 2023
6. Buy ID: 26,  Sell ID: 21,    Price: 100.75,  Quantity: 75,   Timestamp: Mon Jul 24 15:05:11 2023
7. Buy ID: 27,  Sell ID: 23,    Price: 102,     Quantity: 75,   Timestamp: Mon Jul 24 15:05:11 2023
8. Buy ID: 31,  Sell ID: 31,    Price: 101.5,   Quantity: 100,  Timestamp: Mon Jul 24 15:05:11 2023
9. Buy ID: 30,  Sell ID: 30,    Price: 100,     Quantity: 50,   Timestamp: Mon Jul 24 15:05:11 2023
10. Buy ID: 29,         Sell ID: 30,    Price: 100,     Quantity: 50,   Timestamp: Mon Jul 24 15:05:11 2023
11. Buy ID: 33,         Sell ID: 37,    Price: 101,     Quantity: 25,   Timestamp: Mon Jul 24 15:05:11 2023
12. Buy ID: 32,         Sell ID: 37,    Price: 101,     Quantity: 50,   Timestamp: Mon Jul 24 15:05:11 2023
13. Buy ID: 29,         Sell ID: 38,    Price: 100,     Quantity: 50,   Timestamp: Mon Jul 24 15:05:11 2023
14. Buy ID: 34,         Sell ID: 40,    Price: 101.5,   Quantity: 25,   Timestamp: Mon Jul 24 15:05:12 2023
15. Buy ID: 34,         Sell ID: 41,    Price: 101.5,   Quantity: 75,   Timestamp: Mon Jul 24 15:05:12 2023
16. Buy ID: 35,         Sell ID: 42,    Price: 100.75,  Quantity: 25,   Timestamp: Mon Jul 24 15:05:12 2023
17. Buy ID: 39,         Sell ID: 45,    Price: 101.25,  Quantity: 25,   Timestamp: Mon Jul 24 15:05:12 2023
18. Buy ID: 43,         Sell ID: 51,    Price: 100,     Quantity: 25,   Timestamp: Mon Jul 24 15:05:12 2023
19. Buy ID: 44,         Sell ID: 50,    Price: 100.75,  Quantity: 25,   Timestamp: Mon Jul 24 15:05:12 2023
20. Buy ID: 46,         Sell ID: 53,    Price: 100.75,  Quantity: 25,   Timestamp: Mon Jul 24 15:05:12 2023
21. Buy ID: 55,         Sell ID: 66,    Price: 100.5,   Quantity: 25,   Timestamp: Mon Jul 24 15:05:12 2023
22. Buy ID: 61,         Sell ID: 71,    Price: 102,     Quantity: 75,   Timestamp: Mon Jul 24 15:05:12 2023
23. Buy ID: 71,         Sell ID: 82,    Price: 100,     Quantity: 25,   Timestamp: Mon Jul 24 15:05:13 2023
24. Buy ID: 82,         Sell ID: 96,    Price: 101.25,  Quantity: 75,   Timestamp: Mon Jul 24 15:05:13 2023
25. Buy ID: 83,         Sell ID: 97,    Price: 101.75,  Quantity: 75,   Timestamp: Mon Jul 24 15:05:13 2023
26. Buy ID: 93,         Sell ID: 106,   Price: 101.5,   Quantity: 50,   Timestamp: Mon Jul 24 15:05:14 2023
27. Buy ID: 92,         Sell ID: 107,   Price: 100.75,  Quantity: 100,  Timestamp: Mon Jul 24 15:05:14 2023
28. Buy ID: 122,        Sell ID: 130,   Price: 100,     Quantity: 25,   Timestamp: Mon Jul 24 15:05:14 2023
29. Buy ID: 142,        Sell ID: 144,   Price: 101,     Quantity: 75,   Timestamp: Mon Jul 24 15:05:15 2023
30. Buy ID: 143,        Sell ID: 145,   Price: 100.5,   Quantity: 25,   Timestamp: Mon Jul 24 15:05:15 2023
31. Buy ID: 149,        Sell ID: 152,   Price: 100,     Quantity: 25,   Timestamp: Mon Jul 24 15:05:15 2023
32. Buy ID: 148,        Sell ID: 152,   Price: 100,     Quantity: 25,   Timestamp: Mon Jul 24 15:05:15 2023
33. Buy ID: 154,        Sell ID: 155,   Price: 101.25,  Quantity: 50,   Timestamp: Mon Jul 24 15:05:15 2023
34. Buy ID: 156,        Sell ID: 156,   Price: 101.5,   Quantity: 25,   Timestamp: Mon Jul 24 15:05:15 2023
35. Buy ID: 157,        Sell ID: 157,   Price: 100.25,  Quantity: 75,   Timestamp: Mon Jul 24 15:05:15 2023
36. Buy ID: 173,        Sell ID: 178,   Price: 100.5,   Quantity: 25,   Timestamp: Mon Jul 24 15:05:16 2023
37. Buy ID: 173,        Sell ID: 177,   Price: 100.5,   Quantity: 25,   Timestamp: Mon Jul 24 15:05:16 2023
38. Buy ID: 174,        Sell ID: 180,   Price: 101,     Quantity: 25,   Timestamp: Mon Jul 24 15:05:16 2023
39. Buy ID: 180,        Sell ID: 189,   Price: 100.75,  Quantity: 25,   Timestamp: Mon Jul 24 15:05:16 2023
40. Buy ID: 185,        Sell ID: 192,   Price: 102,     Quantity: 50,   Timestamp: Mon Jul 24 15:05:16 2023
41. Buy ID: 190,        Sell ID: 195,   Price: 100,     Quantity: 25,   Timestamp: Mon Jul 24 15:05:16 2023
42. Buy ID: 192,        Sell ID: 200,   Price: 101.75,  Quantity: 25,   Timestamp: Mon Jul 24 15:05:17 2023
43. Buy ID: 195,        Sell ID: 201,   Price: 100,     Quantity: 75,   Timestamp: Mon Jul 24 15:05:17 2023
44. Buy ID: 201,        Sell ID: 202,   Price: 100.25,  Quantity: 25,   Timestamp: Mon Jul 24 15:05:17 2023
45. Buy ID: 207,        Sell ID: 200,   Price: 101.75,  Quantity: 25,   Timestamp: Mon Jul 24 15:05:17 2023
46. Buy ID: 214,        Sell ID: 208,   Price: 101,     Quantity: 50,   Timestamp: Mon Jul 24 15:05:17 2023
47. Buy ID: 231,        Sell ID: 230,   Price: 100.5,   Quantity: 25,   Timestamp: Mon Jul 24 15:05:18 2023
48. Buy ID: 232,        Sell ID: 231,   Price: 101.75,  Quantity: 75,   Timestamp: Mon Jul 24 15:05:18 2023
49. Buy ID: 235,        Sell ID: 235,   Price: 100.25,  Quantity: 75,   Timestamp: Mon Jul 24 15:05:18 2023
50. Buy ID: 238,        Sell ID: 238,   Price: 101,     Quantity: 25,   Timestamp: Mon Jul 24 15:05:18 2023
51. Buy ID: 241,        Sell ID: 240,   Price: 101.25,  Quantity: 25,   Timestamp: Mon Jul 24 15:05:18 2023
52. Buy ID: 242,        Sell ID: 245,   Price: 102,     Quantity: 25,   Timestamp: Mon Jul 24 15:05:18 2023
53. Buy ID: 243,        Sell ID: 249,   Price: 100.25,  Quantity: 25,   Timestamp: Mon Jul 24 15:05:18 2023
54. Buy ID: 247,        Sell ID: 257,   Price: 101,     Quantity: 25,   Timestamp: Mon Jul 24 15:05:18 2023
55. Buy ID: 252,        Sell ID: 260,   Price: 101.5,   Quantity: 50,   Timestamp: Mon Jul 24 15:05:18 2023
56. Buy ID: 257,        Sell ID: 262,   Price: 100.25,  Quantity: 75,   Timestamp: Mon Jul 24 15:05:19 2023
57. Buy ID: 259,        Sell ID: 266,   Price: 102,     Quantity: 25,   Timestamp: Mon Jul 24 15:05:19 2023
58. Buy ID: 259,        Sell ID: 267,   Price: 102,     Quantity: 75,   Timestamp: Mon Jul 24 15:05:19 2023
59. Buy ID: 261,        Sell ID: 268,   Price: 100.5,   Quantity: 50,   Timestamp: Mon Jul 24 15:05:19 2023
60. Buy ID: 268,        Sell ID: 275,   Price: 100,     Quantity: 25,   Timestamp: Mon Jul 24 15:05:19 2023
61. Buy ID: 274,        Sell ID: 279,   Price: 101.75,  Quantity: 75,   Timestamp: Mon Jul 24 15:05:19 2023
62. Buy ID: 282,        Sell ID: 287,   Price: 101.5,   Quantity: 25,   Timestamp: Mon Jul 24 15:05:19 2023
63. Buy ID: 288,        Sell ID: 286,   Price: 101.25,  Quantity: 25,   Timestamp: Mon Jul 24 15:05:19 2023
64. Buy ID: 291,        Sell ID: 288,   Price: 101.5,   Quantity: 75,   Timestamp: Mon Jul 24 15:05:20 2023
65. Buy ID: 295,        Sell ID: 292,   Price: 100,     Quantity: 50,   Timestamp: Mon Jul 24 15:05:20 2023
66. Buy ID: 294,        Sell ID: 293,   Price: 100.5,   Quantity: 25,   Timestamp: Mon Jul 24 15:05:20 2023
67. Buy ID: 297,        Sell ID: 297,   Price: 100,     Quantity: 25,   Timestamp: Mon Jul 24 15:05:20 2023
68. Buy ID: 298,        Sell ID: 301,   Price: 101.5,   Quantity: 25,   Timestamp: Mon Jul 24 15:05:20 2023
69. Buy ID: 299,        Sell ID: 300,   Price: 101,     Quantity: 75,   Timestamp: Mon Jul 24 15:05:20 2023
70. Buy ID: 302,        Sell ID: 304,   Price: 100,     Quantity: 25,   Timestamp: Mon Jul 24 15:05:20 2023
71. Buy ID: 318,        Sell ID: 313,   Price: 100.75,  Quantity: 25,   Timestamp: Mon Jul 24 15:05:20 2023
72. Buy ID: 320,        Sell ID: 319,   Price: 100.75,  Quantity: 75,   Timestamp: Mon Jul 24 15:05:21 2023
73. Buy ID: 322,        Sell ID: 318,   Price: 101.5,   Quantity: 25,   Timestamp: Mon Jul 24 15:05:21 2023
